Workbook

Sheet Composición
A1: Código | B1: Grupo alimentario | C1: Subgrupo alimentario | D1: Nombre | E1: Sinonimo | F1: Precio por libra | G1: P. comestible (por 1 g) | H1: Energía (kcal) | I1: Agua (g) | J1: Alcohol (g) | K1: Proteínas (g) | L1: H. de Carbono (g) | M1: Almidón (g) | N1: Azúcares sencillos (g) | O1: Azúcares libres (g) | P1: Fibra vegetal (g) | Q1: Grasa total (g) | R1: AGS (g) | S1: AGM (g) | T1: AGP (g) | U1: Colesterol (mg) | V1: Vitamina A Eq. Retinol (µg) | W1: Retinol (µg) | X1: Carotenoides Eq. ß-caroteno (µg) | Y1: Vit. D (µg) | Z1: Vit. E Eq. a-tocoferol (mg) | AA1: Vit. K (µg) | AB1: Vitamina B1 (mg) | AC1: Vitamina B2 (mg) | AD1: Eq. de Niacina (mg) | AE1: Vit. B6 (mg) | AF1: Eq. Folato dietético (µg) | AG1: Vit. B12 (µg) | AH1: Pantoténico (mg) | AI1: Biotina (µg) | AJ1: Vit. C (mg) | AK1: Calcio (mg) | AL1: Fósforo (mg) | AM1: Hierro (mg) | AN1: Iodo (µg) | AO1: Cinc (mg) | AP1: Magnesio (mg) | AQ1: Sodio (mg) | AR1: Potasio (mg) | AS1: Manganeso (mg) | AT1: Cobre (mg) | AU1: Selenio (µg) | AV1: Omega-3 (g) | AW1: Tipo_Omega_3 | AX1: Grasas Trans (g) | AY1: Polifenoles (mg) | AZ1: Probióticos (Billones UFC) | BA1: Densidad_Proteica | BB1: Densidad_Fibra | BC1: Densidad_Calcio | BD1: Densidad_Hierro | BE1: Densidad_Sodio | BF1: Relacion_AGP_AGS | BG1: Relacion_Ca_P | BH1: Carga_Grasa_Saturada | BI1: Retención de Líquidos | BJ1: Proporción de Azúcar en el Carbohidrato | BK1: Ratio Fibra | BL1: Porcentaje de Calorías provenientes de las Grasas | BM1: Densidad de Magnesio | BN1: Etiqueta de Densidad Proteica | BO1: Etiqueta Densidad Fibra | BP1: Etiqueta Densidad Calcio | BQ1: Etiqueta Densidad Hierro | BR1: Etiqueta Densidad Sodio | BS1: Etiqueta Relación AGP / AGS | BT1: Etiqueta Porcentaje de Calorías de las Grasas | BU1: Retención de Líquidos (Na / K) | BV1: Etiqueta Densidad Magnesio | BW1: Etiqueta_Omega_3 | BX1: Etiqueta_Grasas_Trans | BY1: Etiqueta_Polifenoles | BZ1: Etiqueta_Probióticos | CA1: Etiqueta_Inflamatorio | CB1: Etiqueta_Irritante | CC1: Índice Inflamatorio de Grasas
A2: 1 | B2: CEREALES | C2: Cereales de desayuno | D2: Malta | F2: 1.5 | G2: 1 | H2: 365 | I2: 9.4 | J2: 0 | K2: 11.2 | L2: 73.1 | M2: 72.4 | N2: 0.66 | O2: 0 | P2: 4.2 | Q2: 2.1 | R2: 0.32 | S2: 0.24 | T2: 0.81 | U2: 0 | V2: 1.8 | W2: 0 | X2: 11 | Y2: 0 | Z2: 2.2 | AA2: 2.8 | AB2: 0.52 | AC2: 0.2 | AD2: 4.7 | AE2: 0.15 | AF2: 57 | AG2: 0 | AH2: 0.68 | AI2: 0 | AJ2: 0 | AK2: 36 | AL2: 349 | AM2: 3.5 | AN2: 0 | AO2: 3.6 | AP2: 111 | AQ2: 17 | AR2: 521 | AS2: 0 | AT2: 0.66 | AU2: 70.7 | AV2: =IFERROR(VLOOKUP(IFERROR(VLOOKUP(D2,Mapa_Similitud!$A$2:$B$2000,2,FALSE()),D2),Hoja1!$A$2:$K$1000,2,FALSE()),IFERROR(VLOOKUP(IFERROR(VLOOKUP(D2,Mapa_Similitud!$A$2:$B$2000,2,FALSE()),D2),Omega3_Referencia!$A$2:$E$100,3,FALSE()),0)) -> 0.03 | AW2: =IFERROR(VLOOKUP(IFERROR(VLOOKUP(D2,Mapa_Similitud!$A$2:$B$2000,2,FALSE()),D2),Hoja1!$A$2:$K$1000,3,FALSE()),IFERROR(VLOOKUP(IFERROR(VLOOKUP(D2,Mapa_Similitud!$A$2:$B$2000,2,FALSE()),D2),Omega3_Referencia!$A$2:$E$100,4,FALSE()),"N/A")) -> ALA | AX2: =IFERROR(VLOOKUP(IFERROR(VLOOKUP(D2,Mapa_Similitud!$A$2:$B$2000,2,FALSE()),D2),Hoja1!$A$2:$K$1000,5,FALSE()),0) -> 0 | AY2: =IFERROR(VLOOKUP(IFERROR(VLOOKUP(D2,Mapa_Similitud!$A$2:$B$2000,2,FALSE()),D2),Hoja1!$A$2:$K$1000,7,FALSE()),0) -> 40 | AZ2: =IFERROR(VLOOKUP(IFERROR(VLOOKUP(D2,Mapa_Similitud!$A$2:$B$2000,2,FALSE()),D2),Hoja1!$A$2:$K$1000,9,FALSE()),0) -> 0 | BA2: =IFERROR(K2/H2,0) -> 0.030684932 | BB2: =IFERROR(P2/H2,0) -> 0.011506849 | BC2: =IFERROR(AK2/H2,0) -> 0.098630137 | BD2: =IFERROR(AM2/H2,0) -> 0.0095890411 | BE2: =IFERROR(AQ2/H2,0) -> 0.046575342 | BF2: =IFERROR(T2/R2,0) -> 2.53125 | BG2: =IFERROR(AK2/AL2,0) -> 0.10315186 | BH2: =IFERROR(R2/Q2,0) -> 0.15238095 | BI2: =IFERROR(AQ2/AR2,0) -> 0.032629559 | BJ2: =IFERROR(N2/L2,0) -> 0.0090287278 | BK2: =IFERROR(P2/L2,0) -> 0.05745554 | BL2: =IFERROR((Q2*9)/H2,0) -> 0.051780822 | BM2: =IFERROR(AP2/H2,0) -> 0.30410959 | BN2: =IF(BA2>0.2,"Muy alta fuente de proteína",IF(BA2>0.15,"Alta fuente de proteína",IF(BA2>0.1,"Media fuente de proteína","Baja fuente de proteína"))) -> Baja fuente de proteína | BO2: =IF(BB2>0.03,"Alta",IF(BB2>0.015,"Media","Baja")) & " fuente de fibra" -> Baja fuente de fibra | BP2: =IF(BC2>1.5,"Alta fuente de calcio",IF(BC2>0.8,"Media fuente de calcio","Baja fuente de calcio")) -> Baja fuente de calcio | BQ2: =IF(BD2>0.015,"Alta fuente de hierro",IF(BD2>0.008,"Media fuente de hierro","Baja fuente de hierro")) -> Media fuente de hierro | BR2: =IF(BE2>2,"Muy alto",IF(BE2>1,"Alto",IF(BE2>0.5,"Moderado","Bajo"))) & " en sodio" -> Bajo en sodio | BS2: =IF(BF2>2,"Altamente antiinflamatorio",IF(BF2>1,"Ligeramente antiinflamatorio",IF(BF2>0.5,"Neutro","Proinflamatorio"))) -> Altamente antiinflamatorio | BT2: =IF(BL2>0.4,"Muy alto en grasas",IF(BL2>0.3,"Alto en grasas",IF(BL2>0.2,"Moderado en grasas","Bajo en grasas"))) -> Bajo en grasas | BU2: =IF(BI2>1,"Alto riesgo de retención de líquidos",IF(BI2>0.5,"Riesgo moderado de retención","Equilibrio de líquidos ideal")) -> Equilibrio de líquidos ideal | BV2: =IF(BM2>0.5,"Alta",IF(BM2>0.2,"Media","Baja")) & " fuente de magnesio" -> Media fuente de magnesio | BW2: =IF(AV2>=0.5,"Alta fuente de Omega 3",IF(AV2>0.1,"Ligera fuente de Omega 3","Sin aporte de Omega 3")) -> Sin aporte de Omega 3 | BX2: =IF(AX2>0.5,"Alerta: Alto en grasas trans",IF(AX2>0,"Contiene grasas trans","Libre de grasas trans")) -> Libre de grasas trans | BY2: =IF(AY2>=50,"Alto",IF(AY2>=10,"Medio","Bajo")) & " poder antioxidante" -> Medio poder antioxidante | BZ2: =IF(AZ2>=1,"Probiótico activo","Sin probióticos") -> Sin probióticos | CA2: =IF(OR(AX2>0.5, O2>15, J2>0), "Altamente inflamatorio", IF(OR(AV2>=0.5, AY2>=50), "Antiinflamatorio", IF(OR(AX2>0, O2>5), "Moderadamente inflamatorio", "Poco inflamatorio"))) -> Poco inflamatorio | CB2: =IF(ISNUMBER(SEARCH("miel", D2)), "No irritante (Uso condicionado SII)", IF(OR(J2>0, ISNUMBER(SEARCH("cacao", D2)), ISNUMBER(SEARCH("chocolate puro", D2))), "Altamente irritante", IF(OR(AND(O2>15, BI2>1), ISNUMBER(SEARCH("chocolate", D2))), "Moderadamente irritante", "No irritante"))) -> No irritante | CC2: =IF(AV2=0,"Sin Omega 3 para evaluar",IFERROR(IF(((T2-AV2)/AV2)>4,"Exceso relativo de Omega 6","Balance de omegas favorable"),"Sin Omega 3 para evaluar")) -> Exceso relativo de Omega 6
A3: =1+A2 -> 2 | B3: CEREALES | C3: Granos y harinas | D3: Arroz | F3: 0.5 | G3: 1 | H3: 364 | I3: 9.4 | J3: 0 | K3: 6.7 | L3: 81.6 | M3: 81.4 | N3: 0.16 | O3: 0 | P3: 1.4 | Q3: 0.9 | R3: 0.19 | S3: 0.23 | T3: 0.32 | U3: 0 | V3: 0 | W3: 0 | X3: 0 | Y3: 0 | Z3: 0.076 | AA3: 1 | AB3: 0.05 | AC3: 0.04 | AD3: 4.9 | AE3: 0.2 | AF3: 20 | AG3: 0 | AH3: 0 | AI3: 3 | AJ3: 20 | AK3: 14 | AL3: 150 | AM3: 0.8 | AN3: 14 | AO3: 1.5 | AP3: 31 | AQ3: 3.9 | AR3: 109 | AS3: 1.2 | AT3: 2 | AU3: 7 | AV3: =IFERROR(VLOOKUP(IFERROR(VLOOKUP(D3,Mapa_Similitud!$A$2:$B$2000,2,FALSE()),D3),Hoja1!$A$2:$K$1000,2,FALSE()),IFERROR(VLOOKUP(IFERROR(VLOOKUP(D3,Mapa_Similitud!$A$2:$B$2000,2,FALSE()),D3),Omega3_Referencia!$A$2:$E$100,3,FALSE()),0)) -> 0.01 | AW3: =IFERROR(VLOOKUP(IFERROR(VLOOKUP(D3,Mapa_Similitud!$A$2:$B$2000,2,FALSE()),D3),Hoja1!$A$2:$K$1000,3,FALSE()),IFERROR(VLOOKUP(IFERROR(VLOOKUP(D3,Mapa_Similitud!$A$2:$B$2000,2,FALSE()),D3),Omega3_Referencia!$A$2:$E$100,4,FALSE()),"N/A")) -> ALA | AX3: =IFERROR(VLOOKUP(IFERROR(VLOOKUP(D3,Mapa_Similitud!$A$2:$B$2000,2,FALSE()),D3),Hoja1!$A$2:$K$1000,5,FALSE()),0) -> 0 | AY3: =IFERROR(VLOOKUP(IFERROR(VLOOKUP(D3,Mapa_Similitud!$A$2:$B$2000,2,FALSE()),D3),Hoja1!$A$2:$K$1000,7,FALSE()),0) -> 1 | AZ3: =IFERROR(VLOOKUP(IFERROR(VLOOKUP(D3,Mapa_Similitud!$A$2:$B$2000,2,FALSE()),D3),Hoja1!$A$2:$K$1000,9,FALSE()),0) -> 0 | BA3: =IFERROR(K3/H3,0) -> 0.018406593 | BB3: =IFERROR(P3/H3,0) -> 0.0038461538 | BC3: =IFERROR(AK3/H3,0) -> 0.038461538 | BD3: =IFERROR(AM3/H3,0) -> 0.0021978022 | BE3: =IFERROR(AQ3/H3,0) -> 0.010714286 | BF3: =IFERROR(T3/R3,0) -> 1.6842105 | BG3: =IFERROR(AK3/AL3,0) -> 0.093333333 | BH3: =IFERROR(R3/Q3,0) -> 0.21111111 | BI3: =IFERROR(AQ3/AR3,0) -> 0.035779817 | BJ3: =IFERROR(N3/L3,0) -> 0.0019607843 | BK3: =IFERROR(P3/L3,0) -> 0.017156863 | BL3: =IFERROR((Q3*9)/H3,0) -> 0.022252747 | BM3: =IFERROR(AP3/H3,0) -> 0.085164835 | BN3: =IF(BA3>0.2,"Muy alta fuente de proteína",IF(BA3>0.15,"Alta fuente de proteína",IF(BA3>0.1,"Media fuente de proteína","Baja fuente de proteína"))) -> Baja fuente de proteína | BO3: =IF(BB3>0.03,"Alta",IF(BB3>0.015,"Media","Baja")) & " fuente de fibra" -> Baja fuente de fibra | BP3: =IF(BC3>1.5,"Alta fuente de calcio",IF(BC3>0.8,"Media fuente de calcio","Baja fuente de calcio")) -> Baja fuente de calcio | BQ3: =IF(BD3>0.015,"Alta fuente de hierro",IF(BD3>0.008,"Media fuente de hierro","Baja fuente de hierro")) -> Baja fuente de hierro | BR3: =IF(BE3>2,"Muy alto",IF(BE3>1,"Alto",IF(BE3>0.5,"Moderado","Bajo"))) & " en sodio" -> Bajo en sodio | BS3: =IF(BF3>2,"Altamente antiinflamatorio",IF(BF3>1,"Ligeramente antiinflamatorio",IF(BF3>0.5,"Neutro","Proinflamatorio"))) -> Ligeramente antiinflamatorio | BT3: =IF(BL3>0.4,"Muy alto en grasas",IF(BL3>0.3,"Alto en grasas",IF(BL3>0.2,"Moderado en grasas","Bajo en grasas"))) -> Bajo en grasas | BU3: =IF(BI3>1,"Alto riesgo de retención de líquidos",IF(BI3>0.5,"Riesgo moderado de retención","Equilibrio de líquidos ideal")) -> Equilibrio de líquidos ideal | BV3: =IF(BM3>0.5,"Alta",IF(BM3>0.2,"Media","Baja")) & " fuente de magnesio" -> Baja fuente de magnesio | BW3: =IF(AV3>=0.5,"Alta fuente de Omega 3",IF(AV3>0.1,"Ligera fuente de Omega 3","Sin aporte de Omega 3")) -> Sin aporte de Omega 3 | BX3: =IF(AX3>0.5,"Alerta: Alto en grasas trans",IF(AX3>0,"Contiene grasas trans","Libre de grasas trans")) -> Libre de grasas trans | BY3: =IF(AY3>=50,"Alto",IF(AY3>=10,"Medio","Bajo")) & " poder antioxidante" -> Bajo poder antioxidante | BZ3: =IF(AZ3>=1,"Probiótico activo","Sin probióticos") -> Sin probióticos | CA3: =IF(OR(AX3>0.5, O3>15, J3>0), "Altamente inflamatorio", IF(OR(AV3>=0.5, AY3>=50), "Antiinflamatorio", IF(OR(AX3>0, O3>5), "Moderadamente inflamatorio", "Poco inflamatorio"))) -> Poco inflamatorio | CB3: =IF(ISNUMBER(SEARCH("miel", D3)), "No irritante (Uso condicionado SII)", IF(OR(J3>0, ISNUMBER(SEARCH("cacao", D3)), ISNUMBER(SEARCH("chocolate puro", D3))), "Altamente irritante", IF(OR(AND(O3>15, BI3>1), ISNUMBER(SEARCH("chocolate", D3))), "Moderadamente irritante", "No irritante"))) -> No irritante | CC3: =IF(AV3=0,"Sin Omega 3 para evaluar",IFERROR(IF(((T3-AV3)/AV3)>4,"Exceso relativo de Omega 6","Balance de omegas favorable"),"Sin Omega 3 para evaluar")) -> Exceso relativo de Omega 6
A4: =1+A3 -> 3 | B4: CEREALES | C4: Granos y harinas | D4: Arroz blanco de cocción rápida | E4: Arroz instantáneo | F4: 0.5 | G4: 1 | H4: 349 | I4: 12.9 | J4: 0 | K4: 6.9 | L4: 78.2 | M4: 78.2 | N4: 0 | O4: 0 | P4: 1.4 | Q4: 0.6 | R4: 0.15 | S4: 0.17 | T4: 0.2 | U4: 0 | V4: 0 | W4: 0 | X4: 0 | Y4: 0 | Z4: 0.1 | AA4: 1 | AB4: 0.22 | AC4: 0.06 | AD4: 4.7 | AE4: 0.38 | AF4: 20 | AG4: 0 | AH4: 1.1 | AI4: 3 | AJ4: 0 | AK4: 34 | AL4: 150 | AM4: 1.4 | AN4: 14 | AO4: 1.8 | AP4: 31 | AQ4: 4 | AR4: 150 | AS4: 1.2 | AT4: 0.37 | AU4: 10 | AV4: =IFERROR(VLOOKUP(IFERROR(VLOOKUP(D4,Mapa_Similitud!$A$2:$B$2000,2,FALSE()),D4),Hoja1!$A$2:$K$1000,2,FALSE()),IFERROR(VLOOKUP(IFERROR(VLOOKUP(D4,Mapa_Similitud!$A$2:$B$2000,2,FALSE()),D4),Omega3_Referencia!$A$2:$E$100,3,FALSE()),0)) -> 0 | AW4: =IFERROR(VLOOKUP(IFERROR(VLOOKUP(D4,Mapa_Similitud!$A$2:$B$2000,2,FALSE()),D4),Hoja1!$A$2:$K$1000,3,FALSE()),IFERROR(VLOOKUP(IFERROR(VLOOKUP(D4,Mapa_Similitud!$A$2:$B$2000,2,FALSE()),D4),Omega3_Referencia!$A$2:$E$100,4,FALSE()),"N/A")) -> N/A | AX4: =IFERROR(VLOOKUP(IFERROR(VLOOKUP(D4,Mapa_Similitud!$A$2:$B$2000,2,FALSE()),D4),Hoja1!$A$2:$K$1000,5,FALSE()),0) -> 0 | AY4: =IFERROR(VLOOKUP(IFERROR(VLOOKUP(D4,Mapa_Similitud!$A$2:$B$2000,2,FALSE()),D4),Hoja1!$A$2:$K$1000,7,FALSE()),0) -> 0 | AZ4: =IFERROR(VLOOKUP(IFERROR(VLOOKUP(D4,Mapa_Similitud!$A$2:$B$2000,2,FALSE()),D4),Hoja1!$A$2:$K$1000,9,FALSE()),0) -> 0 | BA4: =IFERROR(K4/H4,0) -> 0.019770774 | BB4: =IFERROR(P4/H4,0) -> 0.0040114613 | BC4: =IFERROR(AK4/H4,0) -> 0.097421203 | BD4: =IFERROR(AM4/H4,0) -> 0.0040114613 | BE4: =IFERROR(AQ4/H4,0) -> 0.011461318 | BF4: =IFERROR(T4/R4,0) -> 1.3333333 | BG4: =IFERROR(AK4/AL4,0) -> 0.22666667 | BH4: =IFERROR(R4/Q4,0) -> 0.25 | BI4: =IFERROR(AQ4/AR4,0) -> 0.026666667 | BJ4: =IFERROR(N4/L4,0) -> 0 | BK4: =IFERROR(P4/L4,0) -> 0.017902813 | BL4: =IFERROR((Q4*9)/H4,0) -> 0.015472779 | BM4: =IFERROR(AP4/H4,0) -> 0.088825215 | BN4: =IF(BA4>0.2,"Muy alta fuente de proteína",IF(BA4>0.15,"Alta fuente de proteína",IF(BA4>0.1,"Media fuente de proteína","Baja fuente de proteína"))) -> Baja fuente de proteína | BO4: =IF(BB4>0.03,"Alta",IF(BB4>0.015,"Media","Baja")) & " fuente de fibra" -> Baja fuente de fibra | BP4: =IF(BC4>1.5,"Alta fuente de calcio",IF(BC4>0.8,"Media fuente de calcio","Baja fuente de calcio")) -> Baja fuente de calcio | BQ4: =IF(BD4>0.015,"Alta fuente de hierro",IF(BD4>0.008,"Media fuente de hierro","Baja fuente de hierro")) -> Baja fuente de hierro | BR4: =IF(BE4>2,"Muy alto",IF(BE4>1,"Alto",IF(BE4>0.5,"Moderado","Bajo"))) & " en sodio" -> Bajo en sodio | BS4: =IF(BF4>2,"Altamente antiinflamatorio",IF(BF4>1,"Ligeramente antiinflamatorio",IF(BF4>0.5,"Neutro","Proinflamatorio"))) -> Ligeramente antiinflamatorio | BT4: =IF(BL4>0.4,"Muy alto en grasas",IF(BL4>0.3,"Alto en grasas",IF(BL4>0.2,"Moderado en grasas","Bajo en grasas"))) -> Bajo en grasas | BU4: =IF(BI4>1,"Alto riesgo de retención de líquidos",IF(BI4>0.5,"Riesgo moderado de retención","Equilibrio de líquidos ideal")) -> Equilibrio de líquidos ideal | BV4: =IF(BM4>0.5,"Alta",IF(BM4>0.2,"Media","Baja")) & " fuente de magnesio" -> Baja fuente de magnesio | BW4: =IF(AV4>=0.5,"Alta fuente de Omega 3",IF(AV4>0.1,"Ligera fuente de Omega 3","Sin aporte de Omega 3")) -> Sin aporte de Omega 3 | BX4: =IF(AX4>0.5,"Alerta: Alto en grasas trans",IF(AX4>0,"Contiene grasas trans","Libre de grasas trans")) -> Libre de grasas trans | BY4: =IF(AY4>=50,"Alto",IF(AY4>=10,"Medio","Bajo")) & " poder antioxidante" -> Bajo poder antioxidante | BZ4: =IF(AZ4>=1,"Probiótico activo","Sin probióticos") -> Sin probióticos | CA4: =IF(OR(AX4>0.5, O4>15, J4>0), "Altamente inflamatorio", IF(OR(AV4>=0.5, AY4>=50), "Antiinflamatorio", IF(OR(AX4>0, O4>5), "Moderadamente inflamatorio", "Poco inflamatorio"))) -> Poco inflamatorio | CB4: =IF(ISNUMBER(SEARCH("miel", D4)), "No irritante (Uso condicionado SII)", IF(OR(J4>0, ISNUMBER(SEARCH("cacao", D4)), ISNUMBER(SEARCH("chocolate puro", D4))), "Altamente irritante", IF(OR(AND(O4>15, BI4>1), ISNUMBER(SEARCH("chocolate", D4))), "Moderadamente irritante", "No irritante"))) -> No irritante | CC4: =IF(AV4=0,"Sin Omega 3 para evaluar",IFERROR(IF(((T4-AV4)/AV4)>4,"Exceso relativo de Omega 6","Balance de omegas favorable"),"Sin Omega 3 para evaluar")) -> Sin Omega 3 para evaluar
A5: =1+A4 -> 4 | B5: CEREALES | C5: Granos y harinas | D5: Arroz integral | F5: 0.8 | G5: 1 | H5: 350 | I5: 14.2 | J5: 0 | K5: 7.3 | L5: 74.1 | M5: 72.7 | N5: 1.4 | O5: 0 | P5: 2.2 | Q5: 2.2 | R5: 0.61 | S5: 0.55 | T5: 0.81 | U5: 0 | V5: 0 | W5: 0 | X5: 0 | Y5: 0 | Z5: 0.74 | AA5: 1 | AB5: 0.41 | AC5: 0.09 | AD5: 6.6 | AE5: 0.28 | AF5: 49 | AG5: 0 | AH5: 1.5 | AI5: 12 | AJ5: 0 | AK5: 21 | AL5: 310 | AM5: 1.7 | AN5: 2.2 | AO5: 1.6 | AP5: 110 | AQ5: 10 | AR5: 238 | AS5: 2.1 | AT5: 0.29 | AU5: 10 | AV5: =IFERROR(VLOOKUP(IFERROR(VLOOKUP(D5,Mapa_Similitud!$A$2:$B$2000,2,FALSE()),D5),Hoja1!$A$2:$K$1000,2,FALSE()),IFERROR(VLOOKUP(IFERROR(VLOOKUP(D5,Mapa_Similitud!$A$2:$B$2000,2,FALSE()),D5),Omega3_Referencia!$A$2:$E$100,3,FALSE()),0)) -> 0.04 | AW5: =IFERROR(VLOOKUP(IFERROR(VLOOKUP(D5,Mapa_Similitud!$A$2:$B$2000,2,FALSE()),D5),Hoja1!$A$2:$K$1000,3,FALSE()),IFERROR(VLOOKUP(IFERROR(VLOOKUP(D5,Mapa_Similitud!$A$2:$B$2000,2,FALSE()),D5),Omega3_Referencia!$A$2:$E$100,4,FALSE()),"N/A")) -> ALA | AX5: =IFERROR(VLOOKUP(IFERROR(VLOOKUP(D5,Mapa_Similitud!$A$2:$B$2000,2,FALSE()),D5),Hoja1!$A$2:$K$1000,5,FALSE()),0) -> 0 | AY5: =IFERROR(VLOOKUP(IFERROR(VLOOKUP(D5,Mapa_Similitud!$A$2:$B$2000,2,FALSE()),D5),Hoja1!$A$2:$K$1000,7,FALSE()),0) -> 25 | AZ5: =IFERROR(VLOOKUP(IFERROR(VLOOKUP(D5,Mapa_Similitud!$A$2:$B$2000,2,FALSE()),D5),Hoja1!$A$2:$K$1000,9,FALSE()),0) -> 0 | BA5: =IFERROR(K5/H5,0) -> 0.020857143 | BB5: =IFERROR(P5/H5,0) -> 0.0062857143 | BC5: =IFERROR(AK5/H5,0) -> 0.06 | BD5: =IFERROR(AM5/H5,0) -> 0.0048571429 | BE5: =IFERROR(AQ5/H5,0) -> 0.028571429 | BF5: =IFERROR(T5/R5,0) -> 1.3278689 | BG5: =IFERROR(AK5/AL5,0) -> 0.067741935 | BH5: =IFERROR(R5/Q5,0) -> 0.27727273 | BI5: =IFERROR(AQ5/AR5,0) -> 0.042016807 | BJ5: =IFERROR(N5/L5,0) -> 0.018893387 | BK5: =IFERROR(P5/L5,0) -> 0.029689609 | BL5: =IFERROR((Q5*9)/H5,0) -> 0.056571429 | BM5: =IFERROR(AP5/H5,0) -> 0.31428571 | BN5: =IF(BA5>0.2,"Muy alta fuente de proteína",IF(BA5>0.15,"Alta fuente de proteína",IF(BA5>0.1,"Media fuente de proteína","Baja fuente de proteína"))) -> Baja fuente de proteína | BO5: =IF(BB5>0.03,"Alta",IF(BB5>0.015,"Media","Baja")) & " fuente de fibra" -> Baja fuente de fibra | BP5: =IF(BC5>1.5,"Alta fuente de calcio",IF(BC5>0.8,"Media fuente de calcio","Baja fuente de calcio")) -> Baja fuente de calcio | BQ5: =IF(BD5>0.015,"Alta fuente de hierro",IF(BD5>0.008,"Media fuente de hierro","Baja fuente de hierro")) -> Baja fuente de hierro | BR5: =IF(BE5>2,"Muy alto",IF(BE5>1,"Alto",IF(BE5>0.5,"Moderado","Bajo"))) & " en sodio" -> Bajo en sodio | BS5: =IF(BF5>2,"Altamente antiinflamatorio",IF(BF5>1,"Ligeramente antiinflamatorio",IF(BF5>0.5,"Neutro","Proinflamatorio"))) -> Ligeramente antiinflamatorio | BT5: =IF(BL5>0.4,"Muy alto en grasas",IF(BL5>0.3,"Alto en grasas",IF(BL5>0.2,"Moderado en grasas","Bajo en grasas"))) -> Bajo en grasas | BU5: =IF(BI5>1,"Alto riesgo de retención de líquidos",IF(BI5>0.5,"Riesgo moderado de retención","Equilibrio de líquidos ideal")) -> Equilibrio de líquidos ideal | BV5: =IF(BM5>0.5,"Alta",IF(BM5>0.2,"Media","Baja")) & " fuente de magnesio" -> Media fuente de magnesio | BW5: =IF(AV5>=0.5,"Alta fuente de Omega 3",IF(AV5>0.1,"Ligera fuente de Omega 3","Sin aporte de Omega 3")) -> Sin aporte de Omega 3 | BX5: =IF(AX5>0.5,"Alerta: Alto en grasas trans",IF(AX5>0,"Contiene grasas trans","Libre de grasas trans")) -> Libre de grasas trans | BY5: =IF(AY5>=50,"Alto",IF(AY5>=10,"Medio","Bajo")) & " poder antioxidante" -> Medio poder antioxidante | BZ5: =IF(AZ5>=1,"Probiótico activo","Sin probióticos") -> Sin probióticos | CA5: =IF(OR(AX5>0.5, O5>15, J5>0), "Altamente inflamatorio", IF(OR(AV5>=0.5, AY5>=50), "Antiinflamatorio", IF(OR(AX5>0, O5>5), "Moderadamente inflamatorio", "Poco inflamatorio"))) -> Poco inflamatorio | CB5: =IF(ISNUMBER(SEARCH("miel", D5)), "No irritante (Uso condicionado SII)", IF(OR(J5>0, ISNUMBER(SEARCH("cacao", D5)), ISNUMBER(SEARCH("chocolate puro", D5))), "Altamente irritante", IF(OR(AND(O5>15, BI5>1), ISNUMBER(SEARCH("chocolate", D5))), "Moderadamente irritante", "No irritante"))) -> No irritante | CC5: =IF(AV5=0,"Sin Omega 3 para evaluar",IFERROR(IF(((T5-AV5)/AV5)>4,"Exceso relativo de Omega 6","Balance de omegas favorable"),"Sin Omega 3 para evaluar")) -> Exceso relativo de Omega 6
A6: =1+A5 -> 5 | B6: CEREALES | C6: Granos y harinas | D6: Avena | F6: 0.5 | G6: 1 | H6: 353 | I6: 15.8 | J6: 0 | K6: 11.7 | L6: 55.7 | M6: 55.7 | N6: 0 | O6: 0 | P6: 9.7 | Q6: 7.1 | R6: 1.5 | S6: 2.6 | T6: 2.9 | U6: 0 | V6: 0 | W6: 0 | X6: 0 | Y6: 0 | Z6: 0.84 | AA6: 50 | AB6: 0.67 | AC6: 0.17 | AD6: 3.4 | AE6: 0.96 | AF6: 33 | AG6: 0 | AH6: 0.71 | AI6: 13 | AJ6: 0 | AK6: 80 | AL6: 342 | AM6: 5.8 | AN6: 7.7 | AO6: 3.2 | AP6: 129 | AQ6: 8.4 | AR6: 355 | AS6: 3.1 | AT6: 0.42 | AU6: 7.1 | AV6: =IFERROR(VLOOKUP(IFERROR(VLOOKUP(D6,Mapa_Similitud!$A$2:$B$2000,2,FALSE()),D6),Hoja1!$A$2:$K$1000,2,FALSE()),IFERROR(VLOOKUP(IFERROR(VLOOKUP(D6,Mapa_Similitud!$A$2:$B$2000,2,FALSE()),D6),Omega3_Referencia!$A$2:$E$100,3,FALSE()),0)) -> 0.11 | AW6: =IFERROR(VLOOKUP(IFERROR(VLOOKUP(D6,Mapa_Similitud!$A$2:$B$2000,2,FALSE()),D6),Hoja1!$A$2:$K$1000,3,FALSE()),IFERROR(VLOOKUP(IFERROR(VLOOKUP(D6,Mapa_Similitud!$A$2:$B$2000,2,FALSE()),D6),Omega3_Referencia!$A$2:$E$100,4,FALSE()),"N/A")) -> ALA | AX6: =IFERROR(VLOOKUP(IFERROR(VLOOKUP(D6,Mapa_Similitud!$A$2:$B$2000,2,FALSE()),D6),Hoja1!$A$2:$K$1000,5,FALSE()),0) -> 0 | AY6: =IFERROR(VLOOKUP(IFERROR(VLOOKUP(D6,Mapa_Similitud!$A$2:$B$2000,2,FALSE()),D6),Hoja1!$A$2:$K$1000,7,FALSE()),0) -> 80 | AZ6: =IFERROR(VLOOKUP(IFERROR(VLOOKUP(D6,Mapa_Similitud!$A$2:$B$2000,2,FALSE()),D6),Hoja1!$A$2:$K$1000,9,FALSE()),0) -> 0 | BA6: =IFERROR(K6/H6,0) -> 0.033144476 | BB6: =IFERROR(P6/H6,0) -> 0.027478754 | BC6: =IFERROR(AK6/H6,0) -> 0.2266289 | BD6: =IFERROR(AM6/H6,0) -> 0.016430595 | BE6: =IFERROR(AQ6/H6,0) -> 0.023796034 | BF6: =IFERROR(T6/R6,0) -> 1.9333333 | BG6: =IFERROR(AK6/AL6,0) -> 0.23391813 | BH6: =IFERROR(R6/Q6,0) -> 0.21126761 | BI6: =IFERROR(AQ6/AR6,0) -> 0.023661972 | BJ6: =IFERROR(N6/L6,0) -> 0 | BK6: =IFERROR(P6/L6,0) -> 0.17414722 | BL6: =IFERROR((Q6*9)/H6,0) -> 0.18101983 | BM6: =IFERROR(AP6/H6,0) -> 0.36543909 | BN6: =IF(BA6>0.2,"Muy alta fuente de proteína",IF(BA6>0.15,"Alta fuente de proteína",IF(BA6>0.1,"Media fuente de proteína","Baja fuente de proteína"))) -> Baja fuente de proteína | BO6: =IF(BB6>0.03,"Alta",IF(BB6>0.015,"Media","Baja")) & " fuente de fibra" -> Media fuente de fibra | BP6: =IF(BC6>1.5,"Alta fuente de calcio",IF(BC6>0.8,"Media fuente de calcio","Baja fuente de calcio")) -> Baja fuente de calcio | BQ6: =IF(BD6>0.015,"Alta fuente de hierro",IF(BD6>0.008,"Media fuente de hierro","Baja fuente de hierro")) -> Alta fuente de hierro | BR6: =IF(BE6>2,"Muy alto",IF(BE6>1,"Alto",IF(BE6>0.5,"Moderado","Bajo"))) & " en sodio" -> Bajo en sodio | BS6: =IF(BF6>2,"Altamente antiinflamatorio",IF(BF6>1,"Ligeramente antiinflamatorio",IF(BF6>0.5,"Neutro","Proinflamatorio"))) -> Ligeramente antiinflamatorio | BT6: =IF(BL6>0.4,"Muy alto en grasas",IF(BL6>0.3,"Alto en grasas",IF(BL6>0.2,"Moderado en grasas","Bajo en grasas"))) -> Bajo en grasas | BU6: =IF(BI6>1,"Alto riesgo de retención de líquidos",IF(BI6>0.5,"Riesgo moderado de retención","Equilibrio de líquidos ideal")) -> Equilibrio de líquidos ideal | BV6: =IF(BM6>0.5,"Alta",IF(BM6>0.2,"Media","Baja")) & " fuente de magnesio" -> Media fuente de magnesio | BW6: =IF(AV6>=0.5,"Alta fuente de Omega 3",IF(AV6>0.1,"Ligera fuente de Omega 3","Sin aporte de Omega 3")) -> Ligera fuente de Omega 3 | BX6: =IF(AX6>0.5,"Alerta: Alto en grasas trans",IF(AX6>0,"Contiene grasas trans","Libre de grasas trans")) -> Libre de grasas trans | BY6: =IF(AY6>=50,"Alto",IF(AY6>=10,"Medio","Bajo")) & " poder antioxidante" -> Alto poder antioxidante | BZ6: =IF(AZ6>=1,"Probiótico activo","Sin probióticos") -> Sin probióticos | CA6: =IF(OR(AX6>0.5, O6>15, J6>0), "Altamente inflamatorio", IF(OR(AV6>=0.5, AY6>=50), "Antiinflamatorio", IF(OR(AX6>0, O6>5), "Moderadamente inflamatorio", "Poco inflamatorio"))) -> Antiinflamatorio | CB6: =IF(ISNUMBER(SEARCH("miel", D6)), "No irritante (Uso condicionado SII)", IF(OR(J6>0, ISNUMBER(SEARCH("cacao", D6)), ISNUMBER(SEARCH("chocolate puro", D6))), "Altamente irritante", IF(OR(AND(O6>15, BI6>1), ISNUMBER(SEARCH("chocolate", D6))), "Moderadamente irritante", "No irritante"))) -> No irritante | CC6: =IF(AV6=0,"Sin Omega 3 para evaluar",IFERROR(IF(((T6-AV6)/AV6)>4,"Exceso relativo de Omega 6","Balance de omegas favorable"),"Sin Omega 3 para evaluar")) -> Exceso relativo de Omega 6
A7: =1+A6 -> 6 | B7: CEREALES | C7: Granos y harinas | D7: Cebada | F7: 1 | G7: 1 | H7: 330 | I7: 10.1 | J7: 0 | K7: 9.9 | L7: 62.1 | M7: 61.3 | N7: 0.8 | O7: 0 | P7: 15.6 | Q7: 1.2 | R7: 0.24 | S7: 0.15 | T7: 0.56 | U7: 0 | V7: 2.2 | W7: 0 | X7: 13 | Y7: 0 | Z7: 0.02 | AA7: 2.2 | AB7: 0.19 | AC7: 0.11 | AD7: 4.6 | AE7: 0.26 | AF7: 23 | AG7: 0 | AH7: 0.28 | AI7: 0 | AJ7: 0 | AK7: 29 | AL7: 221 | AM7: 2.5 | AN7: 0 | AO7: 2.1 | AP7: 79 | AQ7: 9 | AR7: 280 | AS7: 1.3 | AT7: 0.42 | AU7: 37.7 | AV7: =IFERROR(VLOOKUP(IFERROR(VLOOKUP(D7,Mapa_Similitud!$A$2:$B$2000,2,FALSE()),D7),Hoja1!$A$2:$K$1000,2,FALSE()),IFERROR(VLOOKUP(IFERROR(VLOOKUP(D7,Mapa_Similitud!$A$2:$B$2000,2,FALSE()),D7),Omega3_Referencia!$A$2:$E$100,3,FALSE()),0)) -> 0.08 | AW7: =IFERROR(VLOOKUP(IFERROR(VLOOKUP(D7,Mapa_Similitud!$A$2:$B$2000,2,FALSE()),D7),Hoja1!$A$2:$K$1000,3,FALSE()),IFERROR(VLOOKUP(IFERROR(VLOOKUP(D7,Mapa_Similitud!$A$2:$B$2000,2,FALSE()),D7),Omega3_Referencia!$A$2:$E$100,4,FALSE()),"N/A")) -> ALA | AX7: =IFERROR(VLOOKUP(IFERROR(VLOOKUP(D7,Mapa_Similitud!$A$2:$B$2000,2,FALSE()),D7),Hoja1!$A$2:$K$1000,5,FALSE()),0) -> 0 | AY7: =IFERROR(VLOOKUP(IFERROR(VLOOKUP(D7,Mapa_Similitud!$A$2:$B$2000,2,FALSE()),D7),Hoja1!$A$2:$K$1000,7,FALSE()),0) -> 72.9 | AZ7: =IFERROR(VLOOKUP(IFERROR(VLOOKUP(D7,Mapa_Similitud!$A$2:$B$2000,2,FALSE()),D7),Hoja1!$A$2:$K$1000,9,FALSE()),0) -> 0 | BA7: =IFERROR(K7/H7,0) -> 0.03 | BB7: =IFERROR(P7/H7,0) -> 0.047272727 | BC7: =IFERROR(AK7/H7,0) -> 0.087878788 | BD7: =IFERROR(AM7/H7,0) -> 0.0075757576 | BE7: =IFERROR(AQ7/H7,0) -> 0.027272727 | BF7: =IFERROR(T7/R7,0) -> 2.3333333 | BG7: =IFERROR(AK7/AL7,0) -> 0.13122172 | BH7: =IFERROR(R7/Q7,0) -> 0.2 | BI7: =IFERROR(AQ7/AR7,0) -> 0.032142857 | BJ7: =IFERROR(N7/L7,0) -> 0.012882448 | BK7: =IFERROR(P7/L7,0) -> 0.25120773 | BL7: =IFERROR((Q7*9)/H7,0) -> 0.032727273 | BM7: =IFERROR(AP7/H7,0) -> 0.23939394 | BN7: =IF(BA7>0.2,"Muy alta fuente de proteína",IF(BA7>0.15,"Alta fuente de proteína",IF(BA7>0.1,"Media fuente de proteína","Baja fuente de proteína"))) -> Baja fuente de proteína | BO7: =IF(BB7>0.03,"Alta",IF(BB7>0.015,"Media","Baja")) & " fuente de fibra" -> Alta fuente de fibra | BP7: =IF(BC7>1.5,"Alta fuente de calcio",IF(BC7>0.8,"Media fuente de calcio","Baja fuente de calcio")) -> Baja fuente de calcio | BQ7: =IF(BD7>0.015,"Alta fuente de hierro",IF(BD7>0.008,"Media fuente de hierro","Baja fuente de hierro")) -> Baja fuente de hierro | BR7: =IF(BE7>2,"Muy alto",IF(BE7>1,"Alto",IF(BE7>0.5,"Moderado","Bajo"))) & " en sodio" -> Bajo en sodio | BS7: =IF(BF7>2,"Altamente antiinflamatorio",IF(BF7>1,"Ligeramente antiinflamatorio",IF(BF7>0.5,"Neutro","Proinflamatorio"))) -> Altamente antiinflamatorio | BT7: =IF(BL7>0.4,"Muy alto en grasas",IF(BL7>0.3,"Alto en grasas",IF(BL7>0.2,"Moderado en grasas","Bajo en grasas"))) -> Bajo en grasas | BU7: =IF(BI7>1,"Alto riesgo de retención de líquidos",IF(BI7>0.5,"Riesgo moderado de retención","Equilibrio de líquidos ideal")) -> Equilibrio de líquidos ideal | BV7: =IF(BM7>0.5,"Alta",IF(BM7>0.2,"Media","Baja")) & " fuente de magnesio" -> Media fuente de magnesio | BW7: =IF(AV7>=0.5,"Alta fuente de Omega 3",IF(AV7>0.1,"Ligera fuente de Omega 3","Sin aporte de Omega 3")) -> Sin aporte de Omega 3 | BX7: =IF(AX7>0.5,"Alerta: Alto en grasas trans",IF(AX7>0,"Contiene grasas trans","Libre de grasas trans")) -> Libre de grasas trans | BY7: =IF(AY7>=50,"Alto",IF(AY7>=10,"Medio","Bajo")) & " poder antioxidante" -> Alto poder antioxidante | BZ7: =IF(AZ7>=1,"Probiótico activo","Sin probióticos") -> Sin probióticos | CA7: =IF(OR(AX7>0.5, O7>15, J7>0), "Altamente inflamatorio", IF(OR(AV7>=0.5, AY7>=50), "Antiinflamatorio", IF(OR(AX7>0, O7>5), "Moderadamente inflamatorio", "Poco inflamatorio"))) -> Antiinflamatorio | CB7: =IF(ISNUMBER(SEARCH("miel", D7)), "No irritante (Uso condicionado SII)", IF(OR(J7>0, ISNUMBER(SEARCH("cacao", D7)), ISNUMBER(SEARCH("chocolate puro", D7))), "Altamente irritante", IF(OR(AND(O7>15, BI7>1), ISNUMBER(SEARCH("chocolate", D7))), "Moderadamente irritante", "No irritante"))) -> No irritante | CC7: =IF(AV7=0,"Sin Omega 3 para evaluar",IFERROR(IF(((T7-AV7)/AV7)>4,"Exceso relativo de Omega 6","Balance de omegas favorable"),"Sin Omega 3 para evaluar")) -> Exceso relativo de Omega 6
A8: =1+A7 -> 7 | B8: CEREALES | C8: Granos y harinas | D8: Centeno | F8: 0.7 | G8: 1 | H8: 372 | I8: 0 | J8: 0 | K8: 14.8 | L8: 65.2 | M8: 64.2 | N8: 1.1 | O8: 0 | P8: 14.6 | Q8: 2.5 | R8: 0.29 | S8: 0.3 | T8: 1.1 | U8: 0 | V8: 1.2 | W8: 0 | X8: 7 | Y8: 0 | Z8: 1.9 | AA8: 5.9 | AB8: 0.32 | AC8: 0.25 | AD8: 4.3 | AE8: 0.29 | AF8: 38 | AG8: 0 | AH8: 1.5 | AI8: 0 | AJ8: 0 | AK8: 33 | AL8: 374 | AM8: 2.7 | AN8: 10 | AO8: 3.7 | AP8: 121 | AQ8: 6 | AR8: 264 | AS8: 0 | AT8: 0.45 | AU8: 35.3 | AV8: =IFERROR(VLOOKUP(IFERROR(VLOOKUP(D8,Mapa_Similitud!$A$2:$B$2000,2,FALSE()),D8),Hoja1!$A$2:$K$1000,2,FALSE()),IFERROR(VLOOKUP(IFERROR(VLOOKUP(D8,Mapa_Similitud!$A$2:$B$2000,2,FALSE()),D8),Omega3_Referencia!$A$2:$E$100,3,FALSE()),0)) -> 0.06 | AW8: =IFERROR(VLOOKUP(IFERROR(VLOOKUP(D8,Mapa_Similitud!$A$2:$B$2000,2,FALSE()),D8),Hoja1!$A$2:$K$1000,3,FALSE()),IFERROR(VLOOKUP(IFERROR(VLOOKUP(D8,Mapa_Similitud!$A$2:$B$2000,2,FALSE()),D8),Omega3_Referencia!$A$2:$E$100,4,FALSE()),"N/A")) -> ALA | AX8: =IFERROR(VLOOKUP(IFERROR(VLOOKUP(D8,Mapa_Similitud!$A$2:$B$2000,2,FALSE()),D8),Hoja1!$A$2:$K$1000,5,FALSE()),0) -> 0 | AY8: =IFERROR(VLOOKUP(IFERROR(VLOOKUP(D8,Mapa_Similitud!$A$2:$B$2000,2,FALSE()),D8),Hoja1!$A$2:$K$1000,7,FALSE()),0) -> 65 | AZ8: =IFERROR(VLOOKUP(IFERROR(VLOOKUP(D8,Mapa_Similitud!$A$2:$B$2000,2,FALSE()),D8),Hoja1!$A$2:$K$1000,9,FALSE()),0) -> 0 | BA8: =IFERROR(K8/H8,0) -> 0.039784946 | BB8: =IFERROR(P8/H8,0) -> 0.039247312 | BC8: =IFERROR(AK8/H8,0) -> 0.088709677 | BD8: =IFERROR(AM8/H8,0) -> 0.0072580645 | BE8: =IFERROR(AQ8/H8,0) -> 0.016129032 | BF8: =IFERROR(T8/R8,0) -> 3.7931034 | BG8: =IFERROR(AK8/AL8,0) -> 0.088235294 | BH8: =IFERROR(R8/Q8,0) -> 0.116 | BI8: =IFERROR(AQ8/AR8,0) -> 0.022727273 | BJ8: =IFERROR(N8/L8,0) -> 0.016871166 | BK8: =IFERROR(P8/L8,0) -> 0.22392638 | BL8: =IFERROR((Q8*9)/H8,0) -> 0.060483871 | BM8: =IFERROR(AP8/H8,0) -> 0.32526882 | BN8: =IF(BA8>0.2,"Muy alta fuente de proteína",IF(BA8>0.15,"Alta fuente de proteína",IF(BA8>0.1,"Media fuente de proteína","Baja fuente de proteína"))) -> Baja fuente de proteína | BO8: =IF(BB8>0.03,"Alta",IF(BB8>0.015,"Media","Baja")) & " fuente de fibra" -> Alta fuente de fibra | BP8: =IF(BC8>1.5,"Alta fuente de calcio",IF(BC8>0.8,"Media fuente de calcio","Baja fuente de calcio")) -> Baja fuente de calcio | BQ8: =IF(BD8>0.015,"Alta fuente de hierro",IF(BD8>0.008,"Media fuente de hierro","Baja fuente de hierro")) -> Baja fuente de hierro | BR8: =IF(BE8>2,"Muy alto",IF(BE8>1,"Alto",IF(BE8>0.5,"Moderado","Bajo"))) & " en sodio" -> Bajo en sodio | BS8: =IF(BF8>2,"Altamente antiinflamatorio",IF(BF8>1,"Ligeramente antiinflamatorio",IF(BF8>0.5,"Neutro","Proinflamatorio"))) -> Altamente antiinflamatorio | BT8: =IF(BL8>0.4,"Muy alto en grasas",IF(BL8>0.3,"Alto en grasas",IF(BL8>0.2,"Moderado en grasas","Bajo en grasas"))) -> Bajo en grasas | BU8: =IF(BI8>1,"Alto riesgo de retención de líquidos",IF(BI8>0.5,"Riesgo moderado de retención","Equilibrio de líquidos ideal")) -> Equilibrio de líquidos ideal | BV8: =IF(BM8>0.5,"Alta",IF(BM8>0.2,"Media","Baja")) & " fuente de magnesio" -> Media fuente de magnesio | BW8: =IF(AV8>=0.5,"Alta fuente de Omega 3",IF(AV8>0.1,"Ligera fuente de Omega 3","Sin aporte de Omega 3")) -> Sin aporte de Omega 3 | BX8: =IF(AX8>0.5,"Alerta: Alto en grasas trans",IF(AX8>0,"Contiene grasas trans","Libre de grasas trans")) -> Libre de grasas trans | BY8: =IF(AY8>=50,"Alto",IF(AY8>=10,"Medio","Bajo")) & " poder antioxidante" -> Alto poder antioxidante | BZ8: =IF(AZ8>=1,"Probiótico activo","Sin probióticos") -> Sin probióticos | CA8: =IF(OR(AX8>0.5, O8>15, J8>0), "Altamente inflamatorio", IF(OR(AV8>=0.5, AY8>=50), "Antiinflamatorio", IF(OR(AX8>0, O8>5), "Moderadamente inflamatorio", "Poco inflamatorio"))) -> Antiinflamatorio | CB8: =IF(ISNUMBER(SEARCH("miel", D8)), "No irritante (Uso condicionado SII)", IF(OR(J8>0, ISNUMBER(SEARCH("cacao", D8)), ISNUMBER(SEARCH("chocolate puro", D8))), "Altamente irritante", IF(OR(AND(O8>15, BI8>1), ISNUMBER(SEARCH("chocolate", D8))), "Moderadamente irritante", "No irritante"))) -> No irritante | CC8: =IF(AV8=0,"Sin Omega 3 para evaluar",IFERROR(IF(((T8-AV8)/AV8)>4,"Exceso relativo de Omega 6","Balance de omegas favorable"),"Sin Omega 3 para evaluar")) -> Exceso relativo de Omega 6
A9: =1+A8 -> 8 | B9: CEREALES | C9: Granos y harinas | D9: Fécula de maíz | E9: Maicena | F9: 0.6 | G9: 1 | H9: 356 | I9: 10.9 | J9: 0 | K9: 0.41 | L9: 88 | M9: 88 | N9: 0 | O9: 0 | P9: 0.6 | Q9: 0.08 | R9: 0.011 | S9: 0.02 | T9: 0.03 | U9: 0 | V9: 0 | W9: 0 | X9: 0 | Y9: 0 | Z9: 0 | AA9: 1 | AB9: 0 | AC9: 0.008 | AD9: 0.03 | AE9: 0.005 | AF9: 1 | AG9: 0 | AH9: 0 | AI9: 0 | AJ9: 0 | AK9: 1 | AL9: 30 | AM9: 0.5 | AN9: 2.5 | AO9: 0.3 | AP9: 2 | AQ9: 3 | AR9: 7 | AS9: 1 | AT9: 0.05 | AU9: 2.8 | AV9: =IFERROR(VLOOKUP(IFERROR(VLOOKUP(D9,Mapa_Similitud!$A$2:$B$2000,2,FALSE()),D9),Hoja1!$A$2:$K$1000,2,FALSE()),IFERROR(VLOOKUP(IFERROR(VLOOKUP(D9,Mapa_Similitud!$A$2:$B$2000,2,FALSE()),D9),Omega3_Referencia!$A$2:$E$100,3,FALSE()),0)) -> 0 | AW9: =IFERROR(VLOOKUP(IFERROR(VLOOKUP(D9,Mapa_Similitud!$A$2:$B$2000,2,FALSE()),D9),Hoja1!$A$2:$K$1000,3,FALSE()),IFERROR(VLOOKUP(IFERROR(VLOOKUP(D9,Mapa_Similitud!$A$2:$B$2000,2,FALSE()),D9),Omega3_Referencia!$A$2:$E$100,4,FALSE()),"N/A")) -> N/A | AX9: =IFERROR(VLOOKUP(IFERROR(VLOOKUP(D9,Mapa_Similitud!$A$2:$B$2000,2,FALSE()),D9),Hoja1!$A$2:$K$1000,5,FALSE()),0) -> 0 | AY9: =IFERROR(VLOOKUP(IFERROR(VLOOKUP(D9,Mapa_Similitud!$A$2:$B$2000,2,FALSE()),D9),Hoja1!$A$2:$K$1000,7,FALSE()),0) -> 0 | AZ9: =IFERROR(VLOOKUP(IFERROR(VLOOKUP(D9,Mapa_Similitud!$A$2:$B$2000,2,FALSE()),D9),Hoja1!$A$2:$K$1000,9,FALSE()),0) -> 0 | BA9: =IFERROR(K9/H9,0) -> 0.0011516854 | BB9: =IFERROR(P9/H9,0) -> 0.0016853933 | BC9: =IFERROR(AK9/H9,0) -> 0.0028089888 | BD9: =IFERROR(AM9/H9,0) -> 0.0014044944 | BE9: =IFERROR(AQ9/H9,0) -> 0.0084269663 | BF9: =IFERROR(T9/R9,0) -> 2.7272727 | BG9: =IFERROR(AK9/AL9,0) -> 0.033333333 | BH9: =IFERROR(R9/Q9,0) -> 0.1375 | BI9: =IFERROR(AQ9/AR9,0) -> 0.42857143 | BJ9: =IFERROR(N9/L9,0) -> 0 | BK9: =IFERROR(P9/L9,0) -> 0.0068181818 | BL9: =IFERROR((Q9*9)/H9,0) -> 0.0020224719 | BM9: =IFERROR(AP9/H9,0) -> 0.0056179775 | BN9: =IF(BA9>0.2,"Muy alta fuente de proteína",IF(BA9>0.15,"Alta fuente de proteína",IF(BA9>0.1,"Media fuente de proteína","Baja fuente de proteína"))) -> Baja fuente de proteína | BO9: =IF(BB9>0.03,"Alta",IF(BB9>0.015,"Media","Baja")) & " fuente de fibra" -> Baja fuente de fibra | BP9: =IF(BC9>1.5,"Alta fuente de calcio",IF(BC9>0.8,"Media fuente de calcio","Baja fuente de calcio")) -> Baja fuente de calcio | BQ9: =IF(BD9>0.015,"Alta fuente de hierro",IF(BD9>0.008,"Media fuente de hierro","Baja fuente de hierro")) -> Baja fuente de hierro | BR9: =IF(BE9>2,"Muy alto",IF(BE9>1,"Alto",IF(BE9>0.5,"Moderado","Bajo"))) & " en sodio" -> Bajo en sodio | BS9: =IF(BF9>2,"Altamente antiinflamatorio",IF(BF9>1,"Ligeramente antiinflamatorio",IF(BF9>0.5,"Neutro","Proinflamatorio"))) -> Altamente antiinflamatorio | BT9: =IF(BL9>0.4,"Muy alto en grasas",IF(BL9>0.3,"Alto en grasas",IF(BL9>0.2,"Moderado en grasas","Bajo en grasas"))) -> Bajo en grasas | BU9: =IF(BI9>1,"Alto riesgo de retención de líquidos",IF(BI9>0.5,"Riesgo moderado de retención","Equilibrio de líquidos ideal")) -> Equilibrio de líquidos ideal | BV9: =IF(BM9>0.5,"Alta",IF(BM9>0.2,"Media","Baja")) & " fuente de magnesio" -> Baja fuente de magnesio | BW9: =IF(AV9>=0.5,"Alta fuente de Omega 3",IF(AV9>0.1,"Ligera fuente de Omega 3","Sin aporte de Omega 3")) -> Sin aporte de Omega 3 | BX9: =IF(AX9>0.5,"Alerta: Alto en grasas trans",IF(AX9>0,"Contiene grasas trans","Libre de grasas trans")) -> Libre de grasas trans | BY9: =IF(AY9>=50,"Alto",IF(AY9>=10,"Medio","Bajo")) & " poder antioxidante" -> Bajo poder antioxidante | BZ9: =IF(AZ9>=1,"Probiótico activo","Sin probióticos") -> Sin probióticos | CA9: =IF(OR(AX9>0.5, O9>15, J9>0), "Altamente inflamatorio", IF(OR(AV9>=0.5, AY9>=50), "Antiinflamatorio", IF(OR(AX9>0, O9>5), "Moderadamente inflamatorio", "Poco inflamatorio"))) -> Poco inflamatorio | CB9: =IF(ISNUMBER(SEARCH("miel", D9)), "No irritante (Uso condicionado SII)", IF(OR(J9>0, ISNUMBER(SEARCH("cacao", D9)), ISNUMBER(SEARCH("chocolate puro", D9))), "Altamente irritante", IF(OR(AND(O9>15, BI9>1), ISNUMBER(SEARCH("chocolate", D9))), "Moderadamente irritante", "No irritante"))) -> No irritante | CC9: =IF(AV9=0,"Sin Omega 3 para evaluar",IFERROR(IF(((T9-AV9)/AV9)>4,"Exceso relativo de Omega 6","Balance de omegas favorable"),"Sin Omega 3 para evaluar")) -> Sin Omega 3 para evaluar
A10: =1+A9 -> 9 | B10: CEREALES | C10: Granos y harinas | D10: Harina de arroz | F10: 1.2 | G10: 1 | H10: 349 | I10: 11.9 | J10: 0 | K10: 7.6 | L10: 78 | M10: 77.9 | N10: 0.12 | O10: 0 | P10: 0 | Q10: 0.7 | R10: 0.2 | S10: 0.22 | T10: 0.19 | U10: 0 | V10: 0 | W10: 0 | X10: 0 | Y10: 0 | Z10: 0.11 | AA10: 0 | AB10: 0.14 | AC10: 0.021 | AD10: 2.6 | AE10: 0.44 | AF10: 4 | AG10: 0 | AH10: 0 | AI10: 0 | AJ10: 0 | AK10: 10 | AL10: 98 | AM10: 0.35 | AN10: 0 | AO10: 0.8 | AP10: 35 | AQ10: 0 | AR10: 76 | AS10: 0 | AT10: 0 | AU10: 0 | AV10: =IFERROR(VLOOKUP(IFERROR(VLOOKUP(D10,Mapa_Similitud!$A$2:$B$2000,2,FALSE()),D10),Hoja1!$A$2:$K$1000,2,FALSE()),IFERROR(VLOOKUP(IFERROR(VLOOKUP(D10,Mapa_Similitud!$A$2:$B$2000,2,FALSE()),D10),Omega3_Referencia!$A$2:$E$100,3,FALSE()),0)) -> 0.01 | AW10: =IFERROR(VLOOKUP(IFERROR(VLOOKUP(D10,Mapa_Similitud!$A$2:$B$2000,2,FALSE()),D10),Hoja1!$A$2:$K$1000,3,FALSE()),IFERROR(VLOOKUP(IFERROR(VLOOKUP(D10,Mapa_Similitud!$A$2:$B$2000,2,FALSE()),D10),Omega3_Referencia!$A$2:$E$100,4,FALSE()),"N/A")) -> ALA | AX10: =IFERROR(VLOOKUP(IFERROR(VLOOKUP(D10,Mapa_Similitud!$A$2:$B$2000,2,FALSE()),D10),Hoja1!$A$2:$K$1000,5,FALSE()),0) -> 0 | AY10: =IFERROR(VLOOKUP(IFERROR(VLOOKUP(D10,Mapa_Similitud!$A$2:$B$2000,2,FALSE()),D10),Hoja1!$A$2:$K$1000,7,FALSE()),0) -> 1 | AZ10: =IFERROR(VLOOKUP(IFERROR(VLOOKUP(D10,Mapa_Similitud!$A$2:$B$2000,2,FALSE()),D10),Hoja1!$A$2:$K$1000,9,FALSE()),0) -> 0 | BA10: =IFERROR(K10/H10,0) -> 0.021776504 | BB10: =IFERROR(P10/H10,0) -> 0 | BC10: =IFERROR(AK10/H10,0) -> 0.028653295 | BD10: =IFERROR(AM10/H10,0) -> 0.0010028653 | BE10: =IFERROR(AQ10/H10,0) -> 0 | BF10: =IFERROR(T10/R10,0) -> 0.95 | BG10: =IFERROR(AK10/AL10,0) -> 0.10204082 | BH10: =IFERROR(R10/Q10,0) -> 0.28571429 | BI10: =IFERROR(AQ10/AR10,0) -> 0 | BJ10: =IFERROR(N10/L10,0) -> 0.0015384615 | BK10: =IFERROR(P10/L10,0) -> 0 | BL10: =IFERROR((Q10*9)/H10,0) -> 0.018051576 | BM10: =IFERROR(AP10/H10,0) -> 0.10028653 | BN10: =IF(BA10>0.2,"Muy alta fuente de proteína",IF(BA10>0.15,"Alta fuente de proteína",IF(BA10>0.1,"Media fuente de proteína","Baja fuente de proteína"))) -> Baja fuente de proteína | BO10: =IF(BB10>0.03,"Alta",IF(BB10>0.015,"Media","Baja")) & " fuente de fibra" -> Baja fuente de fibra | BP10: =IF(BC10>1.5,"Alta fuente de calcio",IF(BC10>0.8,"Media fuente de calcio","Baja fuente de calcio")) -> Baja fuente de calcio | BQ10: =IF(BD10>0.015,"Alta fuente de hierro",IF(BD10>0.008,"Media fuente de hierro","Baja fuente de hierro")) -> Baja fuente de hierro | BR10: =IF(BE10>2,"Muy alto",IF(BE10>1,"Alto",IF(BE10>0.5,"Moderado","Bajo"))) & " en sodio" -> Bajo en sodio | BS10: =IF(BF10>2,"Altamente antiinflamatorio",IF(BF10>1,"Ligeramente antiinflamatorio",IF(BF10>0.5,"Neutro","Proinflamatorio"))) -> Neutro | BT10: =IF(BL10>0.4,"Muy alto en grasas",IF(BL10>0.3,"Alto en grasas",IF(BL10>0.2,"Moderado en grasas","Bajo en grasas"))) -> Bajo en grasas | BU10: =IF(BI10>1,"Alto riesgo de retención de líquidos",IF(BI10>0.5,"Riesgo moderado de retención","Equilibrio de líquidos ideal")) -> Equilibrio de líquidos ideal | BV10: =IF(BM10>0.5,"Alta",IF(BM10>0.2,"Media","Baja")) & " fuente de magnesio" -> Baja fuente de magnesio | BW10: =IF(AV10>=0.5,"Alta fuente de Omega 3",IF(AV10>0.1,"Ligera fuente de Omega 3","Sin aporte de Omega 3")) -> Sin aporte de Omega 3 | BX10: =IF(AX10>0.5,"Alerta: Alto en grasas trans",IF(AX10>0,"Contiene grasas trans","Libre de grasas trans")) -> Libre de grasas trans | BY10: =IF(AY10>=50,"Alto",IF(AY10>=10,"Medio","Bajo")) & " poder antioxidante" -> Bajo poder antioxidante | BZ10: =IF(AZ10>=1,"Probiótico activo","Sin probióticos") -> Sin probióticos | CA10: =IF(OR(AX10>0.5, O10>15, J10>0), "Altamente inflamatorio", IF(OR(AV10>=0.5, AY10>=50), "Antiinflamatorio", IF(OR(AX10>0, O10>5), "Moderadamente inflamatorio", "Poco inflamatorio"))) -> Poco inflamatorio | CB10: =IF(ISNUMBER(SEARCH("miel", D10)), "No irritante (Uso condicionado SII)", IF(OR(J10>0, ISNUMBER(SEARCH("cacao", D10)), ISNUMBER(SEARCH("chocolate puro", D10))), "Altamente irritante", IF(OR(AND(O10>15, BI10>1), ISNUMBER(SEARCH("chocolate", D10))), "Moderadamente irritante", "No irritante"))) -> No irritante | CC10: =IF(AV10=0,"Sin Omega 3 para evaluar",IFERROR(IF(((T10-AV10)/AV10)>4,"Exceso relativo de Omega 6","Balance de omegas favorable"),"Sin Omega 3 para evaluar")) -> Exceso relativo de Omega 6
A11: =1+A10 -> 10 | B11: CEREALES | C11: Granos y harinas | D11: Harina de centeno | F11: 1.5 | G11: 1 | H11: 326 | I11: 13.4 | J11: 0 | K11: 10 | L11: 59.7 | M11: 59.7 | N11: 0 | O11: 0 | P11: 15 | Q11: 1.9 | R11: 0.24 | S11: 0.2 | T11: 0.85 | U11: 0 | V11: 0 | W11: 0 | X11: 0 | Y11: 0 | Z11: 1.5 | AA11: 0 | AB11: 0.3 | AC11: 0.2 | AD11: 1.6 | AE11: 0.3 | AF11: 70 | AG11: 0 | AH11: 0 | AI11: 0 | AJ11: 0 | AK11: 27 | AL11: 286 | AM11: 2.6 | AN11: 0 | AO11: 3 | AP11: 82 | AQ11: 2 | AR11: 390 | AS11: 0 | AT11: 0 | AU11: 14.4 | AV11: =IFERROR(VLOOKUP(IFERROR(VLOOKUP(D11,Mapa_Similitud!$A$2:$B$2000,2,FALSE()),D11),Hoja1!$A$2:$K$1000,2,FALSE()),IFERROR(VLOOKUP(IFERROR(VLOOKUP(D11,Mapa_Similitud!$A$2:$B$2000,2,FALSE()),D11),Omega3_Referencia!$A$2:$E$100,3,FALSE()),0)) -> 0.04 | AW11: =IFERROR(VLOOKUP(IFERROR(VLOOKUP(D11,Mapa_Similitud!$A$2:$B$2000,2,FALSE()),D11),Hoja1!$A$2:$K$1000,3,FALSE()),IFERROR(VLOOKUP(IFERROR(VLOOKUP(D11,Mapa_Similitud!$A$2:$B$2000,2,FALSE()),D11),Omega3_Referencia!$A$2:$E$100,4,FALSE()),"N/A")) -> ALA | AX11: =IFERROR(VLOOKUP(IFERROR(VLOOKUP(D11,Mapa_Similitud!$A$2:$B$2000,2,FALSE()),D11),Hoja1!$A$2:$K$1000,5,FALSE()),0) -> 0 | AY11: =IFERROR(VLOOKUP(IFERROR(VLOOKUP(D11,Mapa_Similitud!$A$2:$B$2000,2,FALSE()),D11),Hoja1!$A$2:$K$1000,7,FALSE()),0) -> 45 | AZ11: =IFERROR(VLOOKUP(IFERROR(VLOOKUP(D11,Mapa_Similitud!$A$2:$B$2000,2,FALSE()),D11),Hoja1!$A$2:$K$1000,9,FALSE()),0) -> 0 | BA11: =IFERROR(K11/H11,0) -> 0.030674847 | BB11: =IFERROR(P11/H11,0) -> 0.04601227 | BC11: =IFERROR(AK11/H11,0) -> 0.082822086 | BD11: =IFERROR(AM11/H11,0) -> 0.0079754601 | BE11: =IFERROR(AQ11/H11,0) -> 0.0061349693 | BF11: =IFERROR(T11/R11,0) -> 3.5416667 | BG11: =IFERROR(AK11/AL11,0) -> 0.094405594 | BH11: =IFERROR(R11/Q11,0) -> 0.12631579 | BI11: =IFERROR(AQ11/AR11,0) -> 0.0051282051 | BJ11: =IFERROR(N11/L11,0) -> 0 | BK11: =IFERROR(P11/L11,0) -> 0.25125628 | BL11: =IFERROR((Q11*9)/H11,0) -> 0.052453988 | BM11: =IFERROR(AP11/H11,0) -> 0.25153374 | BN11: =IF(BA11>0.2,"Muy alta fuente de proteína",IF(BA11>0.15,"Alta fuente de proteína",IF(BA11>0.1,"Media fuente de proteína","Baja fuente de proteína"))) -> Baja fuente de proteína | BO11: =IF(BB11>0.03,"Alta",IF(BB11>0.015,"Media","Baja")) & " fuente de fibra" -> Alta fuente de fibra | BP11: =IF(BC11>1.5,"Alta fuente de calcio",IF(BC11>0.8,"Media fuente de calcio","Baja fuente de calcio")) -> Baja fuente de calcio | BQ11: =IF(BD11>0.015,"Alta fuente de hierro",IF(BD11>0.008,"Media fuente de hierro","Baja fuente de hierro")) -> Baja fuente de hierro | BR11: =IF(BE11>2,"Muy alto",IF(BE11>1,"Alto",IF(BE11>0.5,"Moderado","Bajo"))) & " en sodio" -> Bajo en sodio | BS11: =IF(BF11>2,"Altamente antiinflamatorio",IF(BF11>1,"Ligeramente antiinflamatorio",IF(BF11>0.5,"Neutro","Proinflamatorio"))) -> Altamente antiinflamatorio | BT11: =IF(BL11>0.4,"Muy alto en grasas",IF(BL11>0.3,"Alto en grasas",IF(BL11>0.2,"Moderado en grasas","Bajo en grasas"))) -> Bajo en grasas | BU11: =IF(BI11>1,"Alto riesgo de retención de líquidos",IF(BI11>0.5,"Riesgo moderado de retención","Equilibrio de líquidos ideal")) -> Equilibrio de líquidos ideal | BV11: =IF(BM11>0.5,"Alta",IF(BM11>0.2,"Media","Baja")) & " fuente de magnesio" -> Media fuente de magnesio | BW11: =IF(AV11>=0.5,"Alta fuente de Omega 3",IF(AV11>0.1,"Ligera fuente de Omega 3","Sin aporte de Omega 3")) -> Sin aporte de Omega 3 | BX11: =IF(AX11>0.5,"Alerta: Alto en grasas trans",IF(AX11>0,"Contiene grasas trans","Libre de grasas trans")) -> Libre de grasas trans | BY11: =IF(AY11>=50,"Alto",IF(AY11>=10,"Medio","Bajo")) & " poder antioxidante" -> Medio poder antioxidante | BZ11: =IF(AZ11>=1,"Probiótico activo","Sin probióticos") -> Sin probióticos | CA11: =IF(OR(AX11>0.5, O11>15, J11>0), "Altamente inflamatorio", IF(OR(AV11>=0.5, AY11>=50), "Antiinflamatorio", IF(OR(AX11>0, O11>5), "Moderadamente inflamatorio", "Poco inflamatorio"))) -> Poco inflamatorio | CB11: =IF(ISNUMBER(SEARCH("miel", D11)), "No irritante (Uso condicionado SII)", IF(OR(J11>0, ISNUMBER(SEARCH("cacao", D11)), ISNUMBER(SEARCH("chocolate puro", D11))), "Altamente irritante", IF(OR(AND(O11>15, BI11>1), ISNUMBER(SEARCH("chocolate", D11))), "Moderadamente irritante", "No irritante"))) -> No irritante | CC11: =IF(AV11=0,"Sin Omega 3 para evaluar",IFERROR(IF(((T11-AV11)/AV11)>4,"Exceso relativo de Omega 6","Balance de omegas favorable"),"Sin Omega 3 para evaluar")) -> Exceso relativo de Omega 6
A12: =1+A11 -> 11 | B12: CEREALES | C12: Granos y harinas | D12: Harina de maíz | F12: 0.6 | G12: 1 | H12: 342 | I12: 13.2 | J12: 0 | K12: 8.3 | L12: 66.3 | M12: 66.3 | N12: 0 | O12: 0 | P12: 9.4 | Q12: 2.8 | R12: 0.35 | S12: 0.88 | T12: 1.4 | U12: 0 | V12: 50 | W12: 0 | X12: 300 | Y12: 0 | Z12: 0 | AA12: 1 | AB12: 0.44 | AC12: 0.13 | AD12: 0.82 | AE12: 0.06 | AF12: 10 | AG12: 0 | AH12: 0.55 | AI12: 6.6 | AJ12: 0 | AK12: 18 | AL12: 39 | AM12: 2.4 | AN12: 80 | AO12: 1.6 | AP12: 47 | AQ12: 0.7 | AR12: 120 | AS12: 0.46 | AT12: 0.13 | AU12: 15.4 | AV12: =IFERROR(VLOOKUP(IFERROR(VLOOKUP(D12,Mapa_Similitud!$A$2:$B$2000,2,FALSE()),D12),Hoja1!$A$2:$K$1000,2,FALSE()),IFERROR(VLOOKUP(IFERROR(VLOOKUP(D12,Mapa_Similitud!$A$2:$B$2000,2,FALSE()),D12),Omega3_Referencia!$A$2:$E$100,3,FALSE()),0)) -> 0.03 | AW12: =IFERROR(VLOOKUP(IFERROR(VLOOKUP(D12,Mapa_Similitud!$A$2:$B$2000,2,FALSE()),D12),Hoja1!$A$2:$K$1000,3,FALSE()),IFERROR(VLOOKUP(IFERROR(VLOOKUP(D12,Mapa_Similitud!$A$2:$B$2000,2,FALSE()),D12),Omega3_Referencia!$A$2:$E$100,4,FALSE()),"N/A")) -> ALA | AX12: =IFERROR(VLOOKUP(IFERROR(VLOOKUP(D12,Mapa_Similitud!$A$2:$B$2000,2,FALSE()),D12),Hoja1!$A$2:$K$1000,5,FALSE()),0) -> 0 | AY12: =IFERROR(VLOOKUP(IFERROR(VLOOKUP(D12,Mapa_Similitud!$A$2:$B$2000,2,FALSE()),D12),Hoja1!$A$2:$K$1000,7,FALSE()),0) -> 10 | AZ12: =IFERROR(VLOOKUP(IFERROR(VLOOKUP(D12,Mapa_Similitud!$A$2:$B$2000,2,FALSE()),D12),Hoja1!$A$2:$K$1000,9,FALSE()),0) -> 0 | BA12: =IFERROR(K12/H12,0) -> 0.024269006 | BB12: =IFERROR(P12/H12,0) -> 0.02748538 | BC12: =IFERROR(AK12/H12,0) -> 0.052631579 | BD12: =IFERROR(AM12/H12,0) -> 0.0070175439 | BE12: =IFERROR(AQ12/H12,0) -> 0.0020467836 | BF12: =IFERROR(T12/R12,0) -> 4 | BG12: =IFERROR(AK12/AL12,0) -> 0.46153846 | BH12: =IFERROR(R12/Q12,0) -> 0.125 | BI12: =IFERROR(AQ12/AR12,0) -> 0.0058333333 | BJ12: =IFERROR(N12/L12,0) -> 0 | BK12: =IFERROR(P12/L12,0) -> 0.14177979 | BL12: =IFERROR((Q12*9)/H12,0) -> 0.073684211 | BM12: =IFERROR(AP12/H12,0) -> 0.1374269 | BN12: =IF(BA12>0.2,"Muy alta fuente de proteína",IF(BA12>0.15,"Alta fuente de proteína",IF(BA12>0.1,"Media fuente de proteína","Baja fuente de proteína"))) -> Baja fuente de proteína | BO12: =IF(BB12>0.03,"Alta",IF(BB12>0.015,"Media","Baja")) & " fuente de fibra" -> Media fuente de fibra | BP12: =IF(BC12>1.5,"Alta fuente de calcio",IF(BC12>0.8,"Media fuente de calcio","Baja fuente de calcio")) -> Baja fuente de calcio | BQ12: =IF(BD12>0.015,"Alta fuente de hierro",IF(BD12>0.008,"Media fuente de hierro","Baja fuente de hierro")) -> Baja fuente de hierro | BR12: =IF(BE12>2,"Muy alto",IF(BE12>1,"Alto",IF(BE12>0.5,"Moderado","Bajo"))) & " en sodio" -> Bajo en sodio | BS12: =IF(BF12>2,"Altamente antiinflamatorio",IF(BF12>1,"Ligeramente antiinflamatorio",IF(BF12>0.5,"Neutro","Proinflamatorio"))) -> Altamente antiinflamatorio | BT12: =IF(BL12>0.4,"Muy alto en grasas",IF(BL12>0.3,"Alto en grasas",IF(BL12>0.2,"Moderado en grasas","Bajo en grasas"))) -> Bajo en grasas | BU12: =IF(BI12>1,"Alto riesgo de retención de líquidos",IF(BI12>0.5,"Riesgo moderado de retención","Equilibrio de líquidos ideal")) -> Equilibrio de líquidos ideal | BV12: =IF(BM12>0.5,"Alta",IF(BM12>0.2,"Media","Baja")) & " fuente de magnesio" -> Baja fuente de magnesio | BW12: =IF(AV12>=0.5,"Alta fuente de Omega 3",IF(AV12>0.1,"Ligera fuente de Omega 3","Sin aporte de Omega 3")) -> Sin aporte de Omega 3 | BX12: =IF(AX12>0.5,"Alerta: Alto en grasas trans",IF(AX12>0,"Contiene grasas trans","Libre de grasas trans")) -> Libre de grasas trans | BY12: =IF(AY12>=50,"Alto",IF(AY12>=10,"Medio","Bajo")) & " poder antioxidante" -> Medio poder antioxidante | BZ12: =IF(AZ12>=1,"Probiótico activo","Sin probióticos") -> Sin probióticos | CA12: =IF(OR(AX12>0.5, O12>15, J12>0), "Altamente inflamatorio", IF(OR(AV12>=0.5, AY12>=50), "Antiinflamatorio", IF(OR(AX12>0, O12>5), "Moderadamente inflamatorio", "Poco inflamatorio"))) -> Poco inflamatorio | CB12: =IF(ISNUMBER(SEARCH("miel", D12)), "No irritante (Uso condicionado SII)", IF(OR(J12>0, ISNUMBER(SEARCH("cacao", D12)), ISNUMBER(SEARCH("chocolate puro", D12))), "Altamente irritante", IF(OR(AND(O12>15, BI12>1), ISNUMBER(SEARCH("chocolate", D12))), "Moderadamente irritante", "No irritante"))) -> No irritante | CC12: =IF(AV12=0,"Sin Omega 3 para evaluar",IFERROR(IF(((T12-AV12)/AV12)>4,"Exceso relativo de Omega 6","Balance de omegas favorable"),"Sin Omega 3 para evaluar")) -> Exceso relativo de Omega 6
A13: =1+A12 -> 12 | B13: CEREALES | C13: Granos y harinas | D13: Harina de trigo | F13: 0.45 | G13: 1 | H13: 341 | I13: 14 | J13: 0 | K13: 9.9 | L13: 70.6 | M13: 69.9 | N13: 0.7 | O13: 0 | P13: 4.3 | Q13: 1.2 | R13: 0.16 | S13: 0.13 | T13: 0.51 | U13: 0 | V13: 0.17 | W13: 0 | X13: 1 | Y13: 0 | Z13: 0.34 | AA13: 32.7 | AB13: 0.11 | AC13: 0.03 | AD13: 2.3 | AE13: 0.1 | AF13: 16 | AG13: 0 | AH13: 0.4 | AI13: 1.1 | AJ13: 0 | AK13: 17 | AL13: 108 | AM13: 1 | AN13: 10 | AO13: 0.78 | AP13: 23 | AQ13: 2 | AR13: 146 | AS13: 0.69 | AT13: 0.14 | AU13: 4 | AV13: =IFERROR(VLOOKUP(IFERROR(VLOOKUP(D13,Mapa_Similitud!$A$2:$B$2000,2,FALSE()),D13),Hoja1!$A$2:$K$1000,2,FALSE()),IFERROR(VLOOKUP(IFERROR(VLOOKUP(D13,Mapa_Similitud!$A$2:$B$2000,2,FALSE()),D13),Omega3_Referencia!$A$2:$E$100,3,FALSE()),0)) -> 0.02 | AW13: =IFERROR(VLOOKUP(IFERROR(VLOOKUP(D13,Mapa_Similitud!$A$2:$B$2000,2,FALSE()),D13),Hoja1!$A$2:$K$1000,3,FALSE()),IFERROR(VLOOKUP(IFERROR(VLOOKUP(D13,Mapa_Similitud!$A$2:$B$2000,2,FALSE()),D13),Omega3_Referencia!$A$2:$E$100,4,FALSE()),"N/A")) -> ALA | AX13: =IFERROR(VLOOKUP(IFERROR(VLOOKUP(D13,Mapa_Similitud!$A$2:$B$2000,2,FALSE()),D13),Hoja1!$A$2:$K$1000,5,FALSE()),0) -> 0 | AY13: =IFERROR(VLOOKUP(IFERROR(VLOOKUP(D13,Mapa_Similitud!$A$2:$B$2000,2,FALSE()),D13),Hoja1!$A$2:$K$1000,7,FALSE()),0) -> 68.3 | AZ13: =IFERROR(VLOOKUP(IFERROR(VLOOKUP(D13,Mapa_Similitud!$A$2:$B$2000,2,FALSE()),D13),Hoja1!$A$2:$K$1000,9,FALSE()),0) -> 0 | BA13: =IFERROR(K13/H13,0) -> 0.029032258 | BB13: =IFERROR(P13/H13,0) -> 0.012609971 | BC13: =IFERROR(AK13/H13,0) -> 0.049853372 | BD13: =IFERROR(AM13/H13,0) -> 0.0029325513 | BE13: =IFERROR(AQ13/H13,0) -> 0.0058651026 | BF13: =IFERROR(T13/R13,0) -> 3.1875 | BG13: =IFERROR(AK13/AL13,0) -> 0.15740741 | BH13: =IFERROR(R13/Q13,0) -> 0.13333333 | BI13: =IFERROR(AQ13/AR13,0) -> 0.01369863 | BJ13: =IFERROR(N13/L13,0) -> 0.0099150142 | BK13: =IFERROR(P13/L13,0) -> 0.060906516 | BL13: =IFERROR((Q13*9)/H13,0) -> 0.031671554 | BM13: =IFERROR(AP13/H13,0) -> 0.06744868 | BN13: =IF(BA13>0.2,"Muy alta fuente de proteína",IF(BA13>0.15,"Alta fuente de proteína",IF(BA13>0.1,"Media fuente de proteína","Baja fuente de proteína"))) -> Baja fuente de proteína | BO13: =IF(BB13>0.03,"Alta",IF(BB13>0.015,"Media","Baja")) & " fuente de fibra" -> Baja fuente de fibra | BP13: =IF(BC13>1.5,"Alta fuente de calcio",IF(BC13>0.8,"Media fuente de calcio","Baja fuente de calcio")) -> Baja fuente de calcio | BQ13: =IF(BD13>0.015,"Alta fuente de hierro",IF(BD13>0.008,"Media fuente de hierro","Baja fuente de hierro")) -> Baja fuente de hierro | BR13: =IF(BE13>2,"Muy alto",IF(BE13>1,"Alto",IF(BE13>0.5,"Moderado","Bajo"))) & " en sodio" -> Bajo en sodio | BS13: =IF(BF13>2,"Altamente antiinflamatorio",IF(BF13>1,"Ligeramente antiinflamatorio",IF(BF13>0.5,"Neutro","Proinflamatorio"))) -> Altamente antiinflamatorio | BT13: =IF(BL13>0.4,"Muy alto en grasas",IF(BL13>0.3,"Alto en grasas",IF(BL13>0.2,"Moderado en grasas","Bajo en grasas"))) -> Bajo en grasas | BU13: =IF(BI13>1,"Alto riesgo de retención de líquidos",IF(BI13>0.5,"Riesgo moderado de retención","Equilibrio de líquidos ideal")) -> Equilibrio de líquidos ideal | BV13: =IF(BM13>0.5,"Alta",IF(BM13>0.2,"Media","Baja")) & " fuente de magnesio" -> Baja fuente de magnesio | BW13: =IF(AV13>=0.5,"Alta fuente de Omega 3",IF(AV13>0.1,"Ligera fuente de Omega 3","Sin aporte de Omega 3")) -> Sin aporte de Omega 3 | BX13: =IF(AX13>0.5,"Alerta: Alto en grasas trans",IF(AX13>0,"Contiene grasas trans","Libre de grasas trans")) -> Libre de grasas trans | BY13: =IF(AY13>=50,"Alto",IF(AY13>=10,"Medio","Bajo")) & " poder antioxidante" -> Alto poder antioxidante | BZ13: =IF(AZ13>=1,"Probiótico activo","Sin probióticos") -> Sin probióticos | CA13: =IF(OR(AX13>0.5, O13>15, J13>0), "Altamente inflamatorio", IF(OR(AV13>=0.5, AY13>=50), "Antiinflamatorio", IF(OR(AX13>0, O13>5), "Moderadamente inflamatorio", "Poco inflamatorio"))) -> Antiinflamatorio | CB13: =IF(ISNUMBER(SEARCH("miel", D13)), "No irritante (Uso condicionado SII)", IF(OR(J13>0, ISNUMBER(SEARCH("cacao", D13)), ISNUMBER(SEARCH("chocolate puro", D13))), "Altamente irritante", IF(OR(AND(O13>15, BI13>1), ISNUMBER(SEARCH("chocolate", D13))), "Moderadamente irritante", "No irritante"))) -> No irritante | CC13: =IF(AV13=0,"Sin Omega 3 para evaluar",IFERROR(IF(((T13-AV13)/AV13)>4,"Exceso relativo de Omega 6","Balance de omegas favorable"),"Sin Omega 3 para evaluar")) -> Exceso relativo de Omega 6
A14: =1+A13 -> 13 | B14: CEREALES | C14: Granos y harinas | D14: Harina integral de trigo | F14: 0.7 | G14: 1 | H14: 322 | I14: 17.8 | J14: 0 | K14: 12.7 | L14: 58.3 | M14: 56.2 | N14: 2.1 | O14: 0 | P14: 9 | Q14: 2.2 | R14: 0.28 | S14: 0.21 | T14: 0.89 | U14: 0 | V14: 0 | W14: 0 | X14: 0 | Y14: 0 | Z14: 1.4 | AA14: 65.5 | AB14: 0.47 | AC14: 0.09 | AD14: 8.2 | AE14: 0.5 | AF14: 57 | AG14: 0 | AH14: 0.8 | AI14: 7 | AJ14: 0 | AK14: 38 | AL14: 320 | AM14: 3.9 | AN14: 0 | AO14: 2.9 | AP14: 120 | AQ14: 3 | AR14: 340 | AS14: 3.1 | AT14: 0.45 | AU14: 53 | AV14: =IFERROR(VLOOKUP(IFERROR(VLOOKUP(D14,Mapa_Similitud!$A$2:$B$2000,2,FALSE()),D14),Hoja1!$A$2:$K$1000,2,FALSE()),IFERROR(VLOOKUP(IFERROR(VLOOKUP(D14,Mapa_Similitud!$A$2:$B$2000,2,FALSE()),D14),Omega3_Referencia!$A$2:$E$100,3,FALSE()),0)) -> 0.07 | AW14: =IFERROR(VLOOKUP(IFERROR(VLOOKUP(D14,Mapa_Similitud!$A$2:$B$2000,2,FALSE()),D14),Hoja1!$A$2:$K$1000,3,FALSE()),IFERROR(VLOOKUP(IFERROR(VLOOKUP(D14,Mapa_Similitud!$A$2:$B$2000,2,FALSE()),D14),Omega3_Referencia!$A$2:$E$100,4,FALSE()),"N/A")) -> ALA | AX14: =IFERROR(VLOOKUP(IFERROR(VLOOKUP(D14,Mapa_Similitud!$A$2:$B$2000,2,FALSE()),D14),Hoja1!$A$2:$K$1000,5,FALSE()),0) -> 0 | AY14: =IFERROR(VLOOKUP(IFERROR(VLOOKUP(D14,Mapa_Similitud!$A$2:$B$2000,2,FALSE()),D14),Hoja1!$A$2:$K$1000,7,FALSE()),0) -> 90.5 | AZ14: =IFERROR(VLOOKUP(IFERROR(VLOOKUP(D14,Mapa_Similitud!$A$2:$B$2000,2,FALSE()),D14),Hoja1!$A$2:$K$1000,9,FALSE()),0) -> 0 | BA14: =IFERROR(K14/H14,0) -> 0.039440994 | BB14: =IFERROR(P14/H14,0) -> 0.027950311 | BC14: =IFERROR(AK14/H14,0) -> 0.11801242 | BD14: =IFERROR(AM14/H14,0) -> 0.012111801 | BE14: =IFERROR(AQ14/H14,0) -> 0.0093167702 | BF14: =IFERROR(T14/R14,0) -> 3.1785714 | BG14: =IFERROR(AK14/AL14,0) -> 0.11875 | BH14: =IFERROR(R14/Q14,0) -> 0.12727273 | BI14: =IFERROR(AQ14/AR14,0) -> 0.0088235294 | BJ14: =IFERROR(N14/L14,0) -> 0.036020583 | BK14: =IFERROR(P14/L14,0) -> 0.15437393 | BL14: =IFERROR((Q14*9)/H14,0) -> 0.061490683 | BM14: =IFERROR(AP14/H14,0) -> 0.37267081 | BN14: =IF(BA14>0.2,"Muy alta fuente de proteína",IF(BA14>0.15,"Alta fuente de proteína",IF(BA14>0.1,"Media fuente de proteína","Baja fuente de proteína"))) -> Baja fuente de proteína | BO14: =IF(BB14>0.03,"Alta",IF(BB14>0.015,"Media","Baja")) & " fuente de fibra" -> Media fuente de fibra | BP14: =IF(BC14>1.5,"Alta fuente de calcio",IF(BC14>0.8,"Media fuente de calcio","Baja fuente de calcio")) -> Baja fuente de calcio | BQ14: =IF(BD14>0.015,"Alta fuente de hierro",IF(BD14>0.008,"Media fuente de hierro","Baja fuente de hierro")) -> Media fuente de hierro | BR14: =IF(BE14>2,"Muy alto",IF(BE14>1,"Alto",IF(BE14>0.5,"Moderado","Bajo"))) & " en sodio" -> Bajo en sodio | BS14: =IF(BF14>2,"Altamente antiinflamatorio",IF(BF14>1,"Ligeramente antiinflamatorio",IF(BF14>0.5,"Neutro","Proinflamatorio"))) -> Altamente antiinflamatorio | BT14: =IF(BL14>0.4,"Muy alto en grasas",IF(BL14>0.3,"Alto en grasas",IF(BL14>0.2,"Moderado en grasas","Bajo en grasas"))) -> Bajo en grasas | BU14: =IF(BI14>1,"Alto riesgo de retención de líquidos",IF(BI14>0.5,"Riesgo moderado de retención","Equilibrio de líquidos ideal")) -> Equilibrio de líquidos ideal | BV14: =IF(BM14>0.5,"Alta",IF(BM14>0.2,"Media","Baja")) & " fuente de magnesio" -> Media fuente de magnesio | BW14: =IF(AV14>=0.5,"Alta fuente de Omega 3",IF(AV14>0.1,"Ligera fuente de Omega 3","Sin aporte de Omega 3")) -> Sin aporte de Omega 3 | BX14: =IF(AX14>0.5,"Alerta: Alto en grasas trans",IF(AX14>0,"Contiene grasas trans","Libre de grasas trans")) -> Libre de grasas trans | BY14: =IF(AY14>=50,"Alto",IF(AY14>=10,"Medio","Bajo")) & " poder antioxidante" -> Alto poder antioxidante | BZ14: =IF(AZ14>=1,"Probiótico activo","Sin probióticos") -> Sin probióticos | CA14: =IF(OR(AX14>0.5, O14>15, J14>0), "Altamente inflamatorio", IF(OR(AV14>=0.5, AY14>=50), "Antiinflamatorio", IF(OR(AX14>0, O14>5), "Moderadamente inflamatorio", "Poco inflamatorio"))) -> Antiinflamatorio | CB14: =IF(ISNUMBER(SEARCH("miel", D14)), "No irritante (Uso condicionado SII)", IF(OR(J14>0, ISNUMBER(SEARCH("cacao", D14)), ISNUMBER(SEARCH("chocolate puro", D14))), "Altamente irritante", IF(OR(AND(O14>15, BI14>1), ISNUMBER(SEARCH("chocolate", D14))), "Moderadamente irritante", "No irritante"))) -> No irritante | CC14: =IF(AV14=0,"Sin Omega 3 para evaluar",IFERROR(IF(((T14-AV14)/AV14)>4,"Exceso relativo de Omega 6","Balance de omegas favorable"),"Sin Omega 3 para evaluar")) -> Exceso relativo de Omega 6
